Workbook
Name act_ID: Action!$B$5
Name act_Name: Action!$B$6
Name act_Country: Action!$B$7
Name act_Authority: Action!$B$8
Name act_Brief: Action!$B$9
Name act_Source: Action!$B$10
Name act_EffDate: Action!$B$11
Name act_Basis: Action!$B$12
Name act_InTransit: Action!$B$13
Name act_EndDate: Action!$B$14
Name act_Rate: Action!$B$15
Name act_RateType: Action!$B$16
Name act_PriorRate: Action!$B$17
Name act_USMCAExempt: Action!$B$18
Name act_Stacking: Action!$B$19
Name act_DefaultBase: Action!$B$20
Name act_Maker: Action!$B$21
Name act_Checker: Action!$B$22
Name act_Checked: Action!$B$23
Name act_ModelVersion: Action!$B$24
Name scope_HTS: Action!$F$5:$F$304
Name scope_Group: Action!$H$5:$H$304
Name excl_HTS: Action!$J$5:$J$304
Name scope_COO: Action!$M$5:$M$54
Name det_Status: Action!$R$5:$R$104
Name det_Displaced: Action!$S$5:$S$104
Name det_Key: Action!$V$5:$V$104
Name det_Check: Action!$W$5:$W$104
Name rate_ID: Action!$Y$5:$Y$34
Name rate_Group: Action!$Z$5:$Z$34
Name rate_COO: Action!$AA$5:$AA$34
Name rate_USMCA: Action!$AB$5:$AB$34
Name rate_Rate: Action!$AC$5:$AC$34
Name rate_Prior: Action!$AD$5:$AD$34
Name rate_Base: Action!$AE$5:$AE$34
Name rate_Displaced: Action!$AF$5:$AF$34
Name rate_Check: Action!$AI$5:$AI$34
Name qty_Period: Items!$K$1
Name mdl_Currency: Items!$K$2

Sheet README
A1: Tariff-Impact Model (template)
A2: Shared by Research (the WHAT) and Standard Cost (the $). One copy per tariff action and importing country.
A3: All sample rows in this template are SYNTHETIC and use a FICTIONAL action. Clear them before real use.
A6: What this workbook is
B7: The one shared model for a tariff action. Research (Hire A) records the WHAT on the Action tab. Standard Cost (Hire B) loads the items on the Items tab. Calc and Summary work out the $ impact with live formulas.
B8: Boundary rule: Research owns scope, HTS, origins, rates, rate lines, duty base rules, dates, stacking and item-level determinations (from the checked Tariff-Impact Brief). Standard Cost owns the item data, landed cost, margin and the Oracle cost update, and never decides scope. Nobody edits the other track's tab; ask on the Jira story instead.
B9: Guide (every tab and formula explained, with sample results and drills): Tariff-Impact Model Guide. Brief: Tariff-Impact Brief Template. Both are in the team OneNote and the onboarding folder.
A11: Colour key and protection
A12: Yellow | B12: Input cell. Type or paste values here only (Paste Special > Values).
A13: Grey | B13: Formula cell. Locked. If a formula looks wrong, raise it with the Manager; never patch it with a typed number.
A14: Green / red / amber | B14: Status from conditional formatting: green = in scope or check passed; red = a CHECK that must be cleared before review; amber = a NOTE that needs one line in the covering note.
A15: Protection | B15: Every tab is protected without a password, so only yellow cells can be changed and rows cannot be inserted or deleted (that would break the row-by-row link between Items and Calc). Unprotect only with the Manager's agreement, and protect again before review.
A17: How to use it (one copy per tariff action and importing country)
A18: 1 | B18: Copy this template. Name the copy TIM_[Action ID]_[import country]_v0.1.xlsx and save it in [COMPANY: tariff model folder]. Link it on the Jira story; never email copies.
A19: 2 | B19: Clear the SAMPLE rows at intake: select the cells and press Delete; never delete rows. Research clears Action (lists, determinations, rate lines) and Review; Standard Cost clears Items and the Summary chapter list the same day.
A20: 3 | B20: Research (maker): fill the Action tab from the checked brief: fields in column B, the HTS scope list with rate groups, the exclusion list, the origin list, item-level determinations and rate lines. Done when Summary B26 and B27 read YES (until Items is loaded, Action column W shows WAIT instead of OK).
A21: 4 | B21: Research checker (Senior or Manager): compare the Action tab with the brief line by line. Log the review on the Review tab.
A22: 5 | B22: Standard Cost (maker): set the quantity period and currency (Items K1:K2), then paste the item extract into Items as values ([COMPANY: Oracle cost extract or warehouse query], with the extract date in column N). One row per item and import country, all values per the Oracle primary unit of measure in column G. Keep HTS, item numbers and origin codes as text.
A23: 6 | B23: Clear every CHECK in Calc column AJ that comes from the Items data. A CHECK caused by the Action tab (Action columns F, J, W or AI, Summary B26, or a rate or scope CHECK in Calc AJ) goes to Research on the Jira story: Research fixes it; Standard Cost never edits Action. Summary B30 must read YES before review.
A24: 7 | B24: Standard Cost checker (Manager): recalculate 3 items by hand, confirm the item count and totals against the extract, confirm the Summary reconciles. Log the review on the Review tab.
A25: 8 | B25: Release: only a version with a checker sign-off on the Review tab goes to the business. Any change after sign-off is a new version and a new review.
A27: Maker-checker rule
B28: Every model released to the business gets a documented second-person review (Senior or Manager): name, date, version, findings. This applies after day 90 too. The maker never signs their own review.
A30: Limits (read before you trust a number)
B31: Ad valorem rates only. Specific or compound rates (per kg, per unit) need an ad valorem equivalent agreed with Research and the checker.
B32: Landed cost change = duty change only. Fees (for example US MPF), freight and brokerage are assumed unchanged. Duty-based taxes (Canada GST, Mexico IVA) are left out because they are normally recoverable; confirm with Finance.
B33: The impact applies the action to the whole quantity period on Items (Annual by default). It does not apply the effective date, in-transit relief, stock already on hand, the end date or supplier price changes.
B34: Duty paid is assumed. Duty deferral or recovery (Mexico IMMEX temporary imports, US drawback) is not modelled: exclude or adjust those flows and say so in the covering note.
B35: Current duty rate and current standard cost come from the Items tab as given. The model assumes the current standard cost already includes duty at the current rate.
B36: Capacity: 250 item rows; 300 HTS prefixes and 300 exclusions; 50 origins; 100 determinations; 30 rate lines. To extend, see the guide.
A38: Template version
B39: Template v2.0, built 2026-10-08 by build/make_tariff_model.py. Owner: BSA Manager. Change the generator script, not a copy of the workbook.

Sheet Action
A1: Action: the WHAT (Research fills this tab from the checked Tariff-Impact Brief)
A2: Standard Cost reads this tab but never changes it. Questions go to Research on the Jira story.
A3: SAMPLE: the values below describe a FICTIONAL action for training. No such action exists.
A4: Field | B4: Value | C4: Where it comes from | E4: In-scope HTS prefix (as written) | F4: Digits (formula) | G4: Annex line or description (source) | H4: Rate group (blank unless rate lines use it) | I4: Excluded HTS prefix (as written) | J4: Digits (formula) | K4: Exclusion basis (source) | M4: Origin in scope (ISO 2) | N4: Country or note | P4: Item number | Q4: Import country | R4: Determination (IN, OUT or blank = scope rules) | S4: Other duty this action displaces on the item (% of customs value) | T4: Reason | U4: Brief ref | V4: Key (formula) | W4: Check (formula) | Y4: Rate line ID (brief Part 7) | Z4: Rate group (blank = all) | AA4: Origin (blank = all listed) | AB4: USMCA-qualifying (Y, N or blank = either) | AC4: Additional rate (% of customs value) | AD4: Earlier rate this line replaces (blank: B17 if B16 = REPLACE; 0% = adds) | AE4: Duty base (FULL or PART; blank = FULL) | AF4: Other duty this line displaces (% of customs value) | AG4: Brief ref | AH4: In-scope items using this line (formula) | AI4: Check (formula)
A5: Action ID | B5: TA-US-FIC-01 | C5: Brief Part 1. Same ID in the brief, this file name and the Jira story. | E5: 7318 | F5: =IF(SUBSTITUTE(SUBSTITUTE(SUBSTITUTE(SUBSTITUTE(CLEAN(E5&"")," ",""),".","")," ",""),"-","")="","",IF(AND(OR(LEN(SUBSTITUTE(SUBSTITUTE(SUBSTITUTE(SUBSTITUTE(CLEAN(E5&"")," ",""),".","")," ",""),"-",""))=2,LEN(SUBSTITUTE(SUBSTITUTE(SUBSTITUTE(SUBSTITUTE(CLEAN(E5&"")," ",""),".","")," ",""),"-",""))=4,LEN(SUBSTITUTE(SUBSTITUTE(SUBSTITUTE(SUBSTITUTE(CLEAN(E5&"")," ",""),".","")," ",""),"-",""))=6,LEN(SUBSTITUTE(SUBSTITUTE(SUBSTITUTE(SUBSTITUTE(CLEAN(E5&"")," ",""),".","")," ",""),"-",""))=8,LEN(SUBSTITUTE(SUBSTITUTE(SUBSTITUTE(SUBSTITUTE(CLEAN(E5&"")," ",""),".","")," ",""),"-",""))=10),IFERROR(TEXT(VALUE(SUBSTITUTE(SUBSTITUTE(SUBSTITUTE(SUBSTITUTE(CLEAN(E5&"")," ",""),".","")," ",""),"-","")),REPT("0",LEN(SUBSTITUTE(SUBSTITUTE(SUBSTITUTE(SUBSTITUTE(CLEAN(E5&"")," ",""),".","")," ",""),"-",""))))=SUBSTITUTE(SUBSTITUTE(SUBSTITUTE(SUBSTITUTE(CLEAN(E5&"")," ",""),".","")," ",""),"-",""),FALSE)),SUBSTITUTE(SUBSTITUTE(SUBSTITUTE(SUBSTITUTE(CLEAN(E5&"")," ",""),".","")," ",""),"-",""),"CHECK: not 2, 4, 6, 8 or 10 digits")) | G5: FICTIONAL Annex I: heading 7318, screws, bolts, nuts, washers, rivets and similar, of iron or steel | H5: 9903.XX.01 | I5: 7318.24 | J5: =IF(SUBSTITUTE(SUBSTITUTE(SUBSTITUTE(SUBSTITUTE(CLEAN(I5&"")," ",""),".","")," ",""),"-","")="","",IF(AND(OR(LEN(SUBSTITUTE(SUBSTITUTE(SUBSTITUTE(SUBSTITUTE(CLEAN(I5&"")," ",""),".","")," ",""),"-",""))=2,LEN(SUBSTITUTE(SUBSTITUTE(SUBSTITUTE(SUBSTITUTE(CLEAN(I5&"")," ",""),".","")," ",""),"-",""))=4,LEN(SUBSTITUTE(SUBSTITUTE(SUBSTITUTE(SUBSTITUTE(CLEAN(I5&"")," ",""),".","")," ",""),"-",""))=6,LEN(SUBSTITUTE(SUBSTITUTE(SUBSTITUTE(SUBSTITUTE(CLEAN(I5&"")," ",""),".","")," ",""),"-",""))=8,LEN(SUBSTITUTE(SUBSTITUTE(SUBSTITUTE(SUBSTITUTE(CLEAN(I5&"")," ",""),".","")," ",""),"-",""))=10),IFERROR(TEXT(VALUE(SUBSTITUTE(SUBSTITUTE(SUBSTITUTE(SUBSTITUTE(CLEAN(I5&"")," ",""),".","")," ",""),"-","")),REPT("0",LEN(SUBSTITUTE(SUBSTITUTE(SUBSTITUTE(SUBSTITUTE(CLEAN(I5&"")," ",""),".","")," ",""),"-",""))))=SUBSTITUTE(SUBSTITUTE(SUBSTITUTE(SUBSTITUTE(CLEAN(I5&"")," ",""),".","")," ",""),"-",""),FALSE)),SUBSTITUTE(SUBSTITUTE(SUBSTITUTE(SUBSTITUTE(CLEAN(I5&"")," ",""),".","")," ",""),"-",""),"CHECK: not 2, 4, 6, 8 or 10 digits")) | K5: FICTIONAL Annex II (1): cotters and cotter pins | M5: XX | N5: Country X (FICTIONAL; XX is an ISO user-assigned code) | P5: SAMPLE-005 | Q5: US | R5: OUT | T5: FICTIONAL Annex II (2): the supplier certifies every shipment for civil aircraft; the certificate of conformity is filed with each entry | U5: Brief 6.4 | V5: =IF(TRIM(CLEAN(SUBSTITUTE(P5&""," "," ")))="","",UPPER(TRIM(CLEAN(SUBSTITUTE(P5&""," "," "))))&"/"&UPPER(TRIM(CLEAN(SUBSTITUTE(Q5&""," "," "))))) | W5: =IF(V5="","",IF(UPPER(TRIM(CLEAN(SUBSTITUTE(Q5&""," "," "))))<>UPPER(TRIM(CLEAN(SUBSTITUTE(act_Country&""," "," ")))),"CHECK: import country must match B7",IF(COUNTIF(det_Key,V5)>1,"CHECK: listed twice",IF(AND(UPPER(TRIM(CLEAN(SUBSTITUTE(R5&""," "," "))))<>"",UPPER(TRIM(CLEAN(SUBSTITUTE(R5&""," "," "))))<>"IN",UPPER(TRIM(CLEAN(SUBSTITUTE(R5&""," "," "))))<>"OUT"),"CHECK: determination must be IN, OUT or blank",IF(AND(S5&""<>"",NOT(ISNUMBER(S5))),"CHECK: displaced rate must be a percentage",IF(AND(UPPER(TRIM(CLEAN(SUBSTITUTE(R5&""," "," "))))="",NOT(ISNUMBER(S5))),"CHECK: enter IN, OUT or a displaced rate",IF(SUMPRODUCT(--(Calc!$AL$5:$AL$254<>""))=0,"WAIT: Items not loaded yet",IF(COUNTIF(Calc!$AL$5:$AL$254,V5)=0,"CHECK: no Items row for this item and import country","OK")))))))) | AH5: =IF(UPPER(TRIM(CLEAN(SUBSTITUTE(Y5&""," "," "))))="","",COUNTIFS(Calc!$O$5:$O$254,UPPER(TRIM(CLEAN(SUBSTITUTE(Y5&""," "," ")))),Calc!$L$5:$L$254,"Y")) | AI5: =IF(AND(UPPER(TRIM(CLEAN(SUBSTITUTE(Y5&""," "," "))))="",UPPER(TRIM(CLEAN(SUBSTITUTE(Z5&""," "," "))))="",UPPER(TRIM(CLEAN(SUBSTITUTE(AA5&""," "," "))))="",UPPER(TRIM(CLEAN(SUBSTITUTE(AB5&""," "," "))))="",UPPER(TRIM(CLEAN(SUBSTITUTE(AE5&""," "," "))))="",AC5&""="",AD5&""="",AF5&""=""),"",IF(UPPER(TRIM(CLEAN(SUBSTITUTE(Y5&""," "," "))))="","CHECK: line ID missing",IF(NOT(ISNUMBER(AC5)),"CHECK: rate missing",IF(OR(AC5<0,AC5>10),"CHECK: rate must be 0% to 1000%",IF(SUMPRODUCT(--(UPPER(TRIM(CLEAN(SUBSTITUTE(rate_ID&""," "," "))))=UPPER(TRIM(CLEAN(SUBSTITUTE(Y5&""," "," "))))))>1,"CHECK: line ID listed twice",IF(AND(UPPER(TRIM(CLEAN(SUBSTITUTE(Z5&""," "," "))))<>"",SUMPRODUCT(--(UPPER(TRIM(CLEAN(SUBSTITUTE(scope_Group&""," "," "))))=UPPER(TRIM(CLEAN(SUBSTITUTE(Z5&""," "," "))))))=0),"CHECK: rate group not on the scope list",IF(AND(UPPER(TRIM(CLEAN(SUBSTITUTE(AA5&""," "," "))))<>"",SUMPRODUCT(--(UPPER(TRIM(CLEAN(SUBSTITUTE(scope_COO&""," "," "))))=UPPER(TRIM(CLEAN(SUBSTITUTE(AA5&""," "," "))))))=0),"CHECK: origin not on the origin list",IF(AND(UPPER(TRIM(CLEAN(SUBSTITUTE(AB5&""," "," "))))<>"",UPPER(TRIM(CLEAN(SUBSTITUTE(AB5&""," "," "))))<>"Y",UPPER(TRIM(CLEAN(SUBSTITUTE(AB5&""," "," "))))<>"N"),"CHECK: USMCA must be Y, N or blank",IF(AND(UPPER(TRIM(CLEAN(SUBSTITUTE(AE5&""," "," "))))<>"",UPPER(TRIM(CLEAN(SUBSTITUTE(AE5&""," "," "))))<>"FULL",UPPER(TRIM(CLEAN(SUBSTITUTE(AE5&""," "," "))))<>"PART"),"CHECK: duty base must be FULL, PART or blank",IF(OR(AND(AD5&""<>"",NOT(ISNUMBER(AD5))),AND(AF5&""<>"",NOT(ISNUMBER(AF5)))),"CHECK: earlier or displaced rate must be a percentage",IF(AC5>1,"NOTE: rate above 100%: check it was entered as a percentage","OK")))))))))))
A6: Action name | B6: FICTIONAL EXAMPLE: US additional duty on iron or steel fasteners (heading 7318) from Country X | C6: Brief Part 1. | F6: =IF(SUBSTITUTE(SUBSTITUTE(SUBSTITUTE(SUBSTITUTE(CLEAN(E6&"")," ",""),".","")," ",""),"-","")="","",IF(AND(OR(LEN(SUBSTITUTE(SUBSTITUTE(SUBSTITUTE(SUBSTITUTE(CLEAN(E6&"")," ",""),".","")," ",""),"-",""))=2,LEN(SUBSTITUTE(SUBSTITUTE(SUBSTITUTE(SUBSTITUTE(CLEAN(E6&"")," ",""),".","")," ",""),"-",""))=4,LEN(SUBSTITUTE(SUBSTITUTE(SUBSTITUTE(SUBSTITUTE(CLEAN(E6&"")," ",""),".","")," ",""),"-",""))=6,LEN(SUBSTITUTE(SUBSTITUTE(SUBSTITUTE(SUBSTITUTE(CLEAN(E6&"")," ",""),".","")," ",""),"-",""))=8,LEN(SUBSTITUTE(SUBSTITUTE(SUBSTITUTE(SUBSTITUTE(CLEAN(E6&"")," ",""),".","")," ",""),"-",""))=10),IFERROR(TEXT(VALUE(SUBSTITUTE(SUBSTITUTE(SUBSTITUTE(SUBSTITUTE(CLEAN(E6&"")," ",""),".","")," ",""),"-","")),REPT("0",LEN(SUBSTITUTE(SUBSTITUTE(SUBSTITUTE(SUBSTITUTE(CLEAN(E6&"")," ",""),".","")," ",""),"-",""))))=SUBSTITUTE(SUBSTITUTE(SUBSTITUTE(SUBSTITUTE(CLEAN(E6&"")," ",""),".","")," ",""),"-",""),FALSE)),SUBSTITUTE(SUBSTITUTE(SUBSTITUTE(SUBSTITUTE(CLEAN(E6&"")," ",""),".","")," ",""),"-",""),"CHECK: not 2, 4, 6, 8 or 10 digits")) | J6: =IF(SUBSTITUTE(SUBSTITUTE(SUBSTITUTE(SUBSTITUTE(CLEAN(I6&"")," ",""),".","")," ",""),"-","")="","",IF(AND(OR(LEN(SUBSTITUTE(SUBSTITUTE(SUBSTITUTE(SUBSTITUTE(CLEAN(I6&"")," ",""),".","")," ",""),"-",""))=2,LEN(SUBSTITUTE(SUBSTITUTE(SUBSTITUTE(SUBSTITUTE(CLEAN(I6&"")," ",""),".","")," ",""),"-",""))=4,LEN(SUBSTITUTE(SUBSTITUTE(SUBSTITUTE(SUBSTITUTE(CLEAN(I6&"")," ",""),".","")," ",""),"-",""))=6,LEN(SUBSTITUTE(SUBSTITUTE(SUBSTITUTE(SUBSTITUTE(CLEAN(I6&"")," ",""),".","")," ",""),"-",""))=8,LEN(SUBSTITUTE(SUBSTITUTE(SUBSTITUTE(SUBSTITUTE(CLEAN(I6&"")," ",""),".","")," ",""),"-",""))=10),IFERROR(TEXT(VALUE(SUBSTITUTE(SUBSTITUTE(SUBSTITUTE(SUBSTITUTE(CLEAN(I6&"")," ",""),".","")," ",""),"-","")),REPT("0",LEN(SUBSTITUTE(SUBSTITUTE(SUBSTITUTE(SUBSTITUTE(CLEAN(I6&"")," ",""),".","")," ",""),"-",""))))=SUBSTITUTE(SUBSTITUTE(SUBSTITUTE(SUBSTITUTE(CLEAN(I6&"")," ",""),".","")," ",""),"-",""),FALSE)),SUBSTITUTE(SUBSTITUTE(SUBSTITUTE(SUBSTITUTE(CLEAN(I6&"")," ",""),".","")," ",""),"-",""),"CHECK: not 2, 4, 6, 8 or 10 digits")) | P6: SAMPLE-003 | Q6: US | S6: 0.1 | T6: Pays FICTIONAL 9903.YY.01 (10%) today; S1 clause 4 switches it off once 9903.XX.01 applies | U6: Brief 6.6, Q5 | V6: =IF(TRIM(CLEAN(SUBSTITUTE(P6&""," "," ")))="","",UPPER(TRIM(CLEAN(SUBSTITUTE(P6&""," "," "))))&"/"&UPPER(TRIM(CLEAN(SUBSTITUTE(Q6&""," "," "))))) | W6: =IF(V6="","",IF(UPPER(TRIM(CLEAN(SUBSTITUTE(Q6&""," "," "))))<>UPPER(TRIM(CLEAN(SUBSTITUTE(act_Country&""," "," ")))),"CHECK: import country must match B7",IF(COUNTIF(det_Key,V6)>1,"CHECK: listed twice",IF(AND(UPPER(TRIM(CLEAN(SUBSTITUTE(R6&""," "," "))))<>"",UPPER(TRIM(CLEAN(SUBSTITUTE(R6&""," "," "))))<>"IN",UPPER(TRIM(CLEAN(SUBSTITUTE(R6&""," "," "))))<>"OUT"),"CHECK: determination must be IN, OUT or blank",IF(AND(S6&""<>"",NOT(ISNUMBER(S6))),"CHECK: displaced rate must be a percentage",IF(AND(UPPER(TRIM(CLEAN(SUBSTITUTE(R6&""," "," "))))="",NOT(ISNUMBER(S6))),"CHECK: enter IN, OUT or a displaced rate",IF(SUMPRODUCT(--(Calc!$AL$5:$AL$254<>""))=0,"WAIT: Items not loaded yet",IF(COUNTIF(Calc!$AL$5:$AL$254,V6)=0,"CHECK: no Items row for this item and import country","OK")))))))) | AH6: =IF(UPPER(TRIM(CLEAN(SUBSTITUTE(Y6&""," "," "))))="","",COUNTIFS(Calc!$O$5:$O$254,UPPER(TRIM(CLEAN(SUBSTITUTE(Y6&""," "," ")))),Calc!$L$5:$L$254,"Y")) | AI6: =IF(AND(UPPER(TRIM(CLEAN(SUBSTITUTE(Y6&""," "," "))))="",UPPER(TRIM(CLEAN(SUBSTITUTE(Z6&""," "," "))))="",UPPER(TRIM(CLEAN(SUBSTITUTE(AA6&""," "," "))))="",UPPER(TRIM(CLEAN(SUBSTITUTE(AB6&""," "," "))))="",UPPER(TRIM(CLEAN(SUBSTITUTE(AE6&""," "," "))))="",AC6&""="",AD6&""="",AF6&""=""),"",IF(UPPER(TRIM(CLEAN(SUBSTITUTE(Y6&""," "," "))))="","CHECK: line ID missing",IF(NOT(ISNUMBER(AC6)),"CHECK: rate missing",IF(OR(AC6<0,AC6>10),"CHECK: rate must be 0% to 1000%",IF(SUMPRODUCT(--(UPPER(TRIM(CLEAN(SUBSTITUTE(rate_ID&""," "," "))))=UPPER(TRIM(CLEAN(SUBSTITUTE(Y6&""," "," "))))))>1,"CHECK: line ID listed twice",IF(AND(UPPER(TRIM(CLEAN(SUBSTITUTE(Z6&""," "," "))))<>"",SUMPRODUCT(--(UPPER(TRIM(CLEAN(SUBSTITUTE(scope_Group&""," "," "))))=UPPER(TRIM(CLEAN(SUBSTITUTE(Z6&""," "," "))))))=0),"CHECK: rate group not on the scope list",IF(AND(UPPER(TRIM(CLEAN(SUBSTITUTE(AA6&""," "," "))))<>"",SUMPRODUCT(--(UPPER(TRIM(CLEAN(SUBSTITUTE(scope_COO&""," "," "))))=UPPER(TRIM(CLEAN(SUBSTITUTE(AA6&""," "," "))))))=0),"CHECK: origin not on the origin list",IF(AND(UPPER(TRIM(CLEAN(SUBSTITUTE(AB6&""," "," "))))<>"",UPPER(TRIM(CLEAN(SUBSTITUTE(AB6&""," "," "))))<>"Y",UPPER(TRIM(CLEAN(SUBSTITUTE(AB6&""," "," "))))<>"N"),"CHECK: USMCA must be Y, N or blank",IF(AND(UPPER(TRIM(CLEAN(SUBSTITUTE(AE6&""," "," "))))<>"",UPPER(TRIM(CLEAN(SUBSTITUTE(AE6&""," "," "))))<>"FULL",UPPER(TRIM(CLEAN(SUBSTITUTE(AE6&""," "," "))))<>"PART"),"CHECK: duty base must be FULL, PART or blank",IF(OR(AND(AD6&""<>"",NOT(ISNUMBER(AD6))),AND(AF6&""<>"",NOT(ISNUMBER(AF6)))),"CHECK: earlier or displaced rate must be a percentage",IF(AC6>1,"NOTE: rate above 100%: check it was entered as a percentage","OK")))))))))))
A7: Importing country (US, CA or MX) | B7: US | C7: Brief Part 1. One model per importing country. | F7: =IF(SUBSTITUTE(SUBSTITUTE(SUBSTITUTE(SUBSTITUTE(CLEAN(E7&"")," ",""),".","")," ",""),"-","")="","",IF(AND(OR(LEN(SUBSTITUTE(SUBSTITUTE(SUBSTITUTE(SUBSTITUTE(CLEAN(E7&"")," ",""),".","")," ",""),"-",""))=2,LEN(SUBSTITUTE(SUBSTITUTE(SUBSTITUTE(SUBSTITUTE(CLEAN(E7&"")," ",""),".","")," ",""),"-",""))=4,LEN(SUBSTITUTE(SUBSTITUTE(SUBSTITUTE(SUBSTITUTE(CLEAN(E7&"")," ",""),".","")," ",""),"-",""))=6,LEN(SUBSTITUTE(SUBSTITUTE(SUBSTITUTE(SUBSTITUTE(CLEAN(E7&"")," ",""),".","")," ",""),"-",""))=8,LEN(SUBSTITUTE(SUBSTITUTE(SUBSTITUTE(SUBSTITUTE(CLEAN(E7&"")," ",""),".","")," ",""),"-",""))=10),IFERROR(TEXT(VALUE(SUBSTITUTE(SUBSTITUTE(SUBSTITUTE(SUBSTITUTE(CLEAN(E7&"")," ",""),".","")," ",""),"-","")),REPT("0",LEN(SUBSTITUTE(SUBSTITUTE(SUBSTITUTE(SUBSTITUTE(CLEAN(E7&"")," ",""),".","")," ",""),"-",""))))=SUBSTITUTE(SUBSTITUTE(SUBSTITUTE(SUBSTITUTE(CLEAN(E7&"")," ",""),".","")," ",""),"-",""),FALSE)),SUBSTITUTE(SUBSTITUTE(SUBSTITUTE(SUBSTITUTE(CLEAN(E7&"")," ",""),".","")," ",""),"-",""),"CHECK: not 2, 4, 6, 8 or 10 digits")) | J7: =IF(SUBSTITUTE(SUBSTITUTE(SUBSTITUTE(SUBSTITUTE(CLEAN(I7&"")," ",""),".","")," ",""),"-","")="","",IF(AND(OR(LEN(SUBSTITUTE(SUBSTITUTE(SUBSTITUTE(SUBSTITUTE(CLEAN(I7&"")," ",""),".","")," ",""),"-",""))=2,LEN(SUBSTITUTE(SUBSTITUTE(SUBSTITUTE(SUBSTITUTE(CLEAN(I7&"")," ",""),".","")," ",""),"-",""))=4,LEN(SUBSTITUTE(SUBSTITUTE(SUBSTITUTE(SUBSTITUTE(CLEAN(I7&"")," ",""),".","")," ",""),"-",""))=6,LEN(SUBSTITUTE(SUBSTITUTE(SUBSTITUTE(SUBSTITUTE(CLEAN(I7&"")," ",""),".","")," ",""),"-",""))=8,LEN(SUBSTITUTE(SUBSTITUTE(SUBSTITUTE(SUBSTITUTE(CLEAN(I7&"")," ",""),".","")," ",""),"-",""))=10),IFERROR(TEXT(VALUE(SUBSTITUTE(SUBSTITUTE(SUBSTITUTE(SUBSTITUTE(CLEAN(I7&"")," ",""),".","")," ",""),"-","")),REPT("0",LEN(SUBSTITUTE(SUBSTITUTE(SUBSTITUTE(SUBSTITUTE(CLEAN(I7&"")," ",""),".","")," ",""),"-",""))))=SUBSTITUTE(SUBSTITUTE(SUBSTITUTE(SUBSTITUTE(CLEAN(I7&"")," ",""),".","")," ",""),"-",""),FALSE)),SUBSTITUTE(SUBSTITUTE(SUBSTITUTE(SUBSTITUTE(CLEAN(I7&"")," ",""),".","")," ",""),"-",""),"CHECK: not 2, 4, 6, 8 or 10 digits")) | V7: =IF(TRIM(CLEAN(SUBSTITUTE(P7&""," "," ")))="","",UPPER(TRIM(CLEAN(SUBSTITUTE(P7&""," "," "))))&"/"&UPPER(TRIM(CLEAN(SUBSTITUTE(Q7&""," "," "))))) | W7: =IF(V7="","",IF(UPPER(TRIM(CLEAN(SUBSTITUTE(Q7&""," "," "))))<>UPPER(TRIM(CLEAN(SUBSTITUTE(act_Country&""," "," ")))),"CHECK: import country must match B7",IF(COUNTIF(det_Key,V7)>1,"CHECK: listed twice",IF(AND(UPPER(TRIM(CLEAN(SUBSTITUTE(R7&""," "," "))))<>"",UPPER(TRIM(CLEAN(SUBSTITUTE(R7&""," "," "))))<>"IN",UPPER(TRIM(CLEAN(SUBSTITUTE(R7&""," "," "))))<>"OUT"),"CHECK: determination must be IN, OUT or blank",IF(AND(S7&""<>"",NOT(ISNUMBER(S7))),"CHECK: displaced rate must be a percentage",IF(AND(UPPER(TRIM(CLEAN(SUBSTITUTE(R7&""," "," "))))="",NOT(ISNUMBER(S7))),"CHECK: enter IN, OUT or a displaced rate",IF(SUMPRODUCT(--(Calc!$AL$5:$AL$254<>""))=0,"WAIT: Items not loaded yet",IF(COUNTIF(Calc!$AL$5:$AL$254,V7)=0,"CHECK: no Items row for this item and import country","OK")))))))) | AH7: =IF(UPPER(TRIM(CLEAN(SUBSTITUTE(Y7&""," "," "))))="","",COUNTIFS(Calc!$O$5:$O$254,UPPER(TRIM(CLEAN(SUBSTITUTE(Y7&""," "," ")))),Calc!$L$5:$L$254,"Y")) | AI7: =IF(AND(UPPER(TRIM(CLEAN(SUBSTITUTE(Y7&""," "," "))))="",UPPER(TRIM(CLEAN(SUBSTITUTE(Z7&""," "," "))))="",UPPER(TRIM(CLEAN(SUBSTITUTE(AA7&""," "," "))))="",UPPER(TRIM(CLEAN(SUBSTITUTE(AB7&""," "," "))))="",UPPER(TRIM(CLEAN(SUBSTITUTE(AE7&""," "," "))))="",AC7&""="",AD7&""="",AF7&""=""),"",IF(UPPER(TRIM(CLEAN(SUBSTITUTE(Y7&""," "," "))))="","CHECK: line ID missing",IF(NOT(ISNUMBER(AC7)),"CHECK: rate missing",IF(OR(AC7<0,AC7>10),"CHECK: rate must be 0% to 1000%",IF(SUMPRODUCT(--(UPPER(TRIM(CLEAN(SUBSTITUTE(rate_ID&""," "," "))))=UPPER(TRIM(CLEAN(SUBSTITUTE(Y7&""," "," "))))))>1,"CHECK: line ID listed twice",IF(AND(UPPER(TRIM(CLEAN(SUBSTITUTE(Z7&""," "," "))))<>"",SUMPRODUCT(--(UPPER(TRIM(CLEAN(SUBSTITUTE(scope_Group&""," "," "))))=UPPER(TRIM(CLEAN(SUBSTITUTE(Z7&""," "," "))))))=0),"CHECK: rate group not on the scope list",IF(AND(UPPER(TRIM(CLEAN(SUBSTITUTE(AA7&""," "," "))))<>"",SUMPRODUCT(--(UPPER(TRIM(CLEAN(SUBSTITUTE(scope_COO&""," "," "))))=UPPER(TRIM(CLEAN(SUBSTITUTE(AA7&""," "," "))))))=0),"CHECK: origin not on the origin list",IF(AND(UPPER(TRIM(CLEAN(SUBSTITUTE(AB7&""," "," "))))<>"",UPPER(TRIM(CLEAN(SUBSTITUTE(AB7&""," "," "))))<>"Y",UPPER(TRIM(CLEAN(SUBSTITUTE(AB7&""," "," "))))<>"N"),"CHECK: USMCA must be Y, N or blank",IF(AND(UPPER(TRIM(CLEAN(SUBSTITUTE(AE7&""," "," "))))<>"",UPPER(TRIM(CLEAN(SUBSTITUTE(AE7&""," "," "))))<>"FULL",UPPER(TRIM(CLEAN(SUBSTITUTE(AE7&""," "," "))))<>"PART"),"CHECK: duty base must be FULL, PART or blank",IF(OR(AND(AD7&""<>"",NOT(ISNUMBER(AD7))),AND(AF7&""<>"",NOT(ISNUMBER(AF7)))),"CHECK: earlier or displaced rate must be a percentage",IF(AC7>1,"NOTE: rate above 100%: check it was entered as a percentage","OK")))))))))))
A8: Legal authority category | B8: Section 301 | C8: Brief Part 3. Category only; the citation goes in B10. | F8: =IF(SUBSTITUTE(SUBSTITUTE(SUBSTITUTE(SUBSTITUTE(CLEAN(E8&"")," ",""),".","")," ",""),"-","")="","",IF(AND(OR(LEN(SUBSTITUTE(SUBSTITUTE(SUBSTITUTE(SUBSTITUTE(CLEAN(E8&"")," ",""),".","")," ",""),"-",""))=2,LEN(SUBSTITUTE(SUBSTITUTE(SUBSTITUTE(SUBSTITUTE(CLEAN(E8&"")," ",""),".","")," ",""),"-",""))=4,LEN(SUBSTITUTE(SUBSTITUTE(SUBSTITUTE(SUBSTITUTE(CLEAN(E8&"")," ",""),".","")," ",""),"-",""))=6,LEN(SUBSTITUTE(SUBSTITUTE(SUBSTITUTE(SUBSTITUTE(CLEAN(E8&"")," ",""),".","")," ",""),"-",""))=8,LEN(SUBSTITUTE(SUBSTITUTE(SUBSTITUTE(SUBSTITUTE(CLEAN(E8&"")," ",""),".","")," ",""),"-",""))=10),IFERROR(TEXT(VALUE(SUBSTITUTE(SUBSTITUTE(SUBSTITUTE(SUBSTITUTE(CLEAN(E8&"")," ",""),".","")," ",""),"-","")),REPT("0",LEN(SUBSTITUTE(SUBSTITUTE(SUBSTITUTE(SUBSTITUTE(CLEAN(E8&"")," ",""),".","")," ",""),"-",""))))=SUBSTITUTE(SUBSTITUTE(SUBSTITUTE(SUBSTITUTE(CLEAN(E8&"")," ",""),".","")," ",""),"-",""),FALSE)),SUBSTITUTE(SUBSTITUTE(SUBSTITUTE(SUBSTITUTE(CLEAN(E8&"")," ",""),".","")," ",""),"-",""),"CHECK: not 2, 4, 6, 8 or 10 digits")) | J8: =IF(SUBSTITUTE(SUBSTITUTE(SUBSTITUTE(SUBSTITUTE(CLEAN(I8&"")," ",""),".","")," ",""),"-","")="","",IF(AND(OR(LEN(SUBSTITUTE(SUBSTITUTE(SUBSTITUTE(SUBSTITUTE(CLEAN(I8&"")," ",""),".","")," ",""),"-",""))=2,LEN(SUBSTITUTE(SUBSTITUTE(SUBSTITUTE(SUBSTITUTE(CLEAN(I8&"")," ",""),".","")," ",""),"-",""))=4,LEN(SUBSTITUTE(SUBSTITUTE(SUBSTITUTE(SUBSTITUTE(CLEAN(I8&"")," ",""),".","")," ",""),"-",""))=6,LEN(SUBSTITUTE(SUBSTITUTE(SUBSTITUTE(SUBSTITUTE(CLEAN(I8&"")," ",""),".","")," ",""),"-",""))=8,LEN(SUBSTITUTE(SUBSTITUTE(SUBSTITUTE(SUBSTITUTE(CLEAN(I8&"")," ",""),".","")," ",""),"-",""))=10),IFERROR(TEXT(VALUE(SUBSTITUTE(SUBSTITUTE(SUBSTITUTE(SUBSTITUTE(CLEAN(I8&"")," ",""),".","")," ",""),"-","")),REPT("0",LEN(SUBSTITUTE(SUBSTITUTE(SUBSTITUTE(SUBSTITUTE(CLEAN(I8&"")," ",""),".","")," ",""),"-",""))))=SUBSTITUTE(SUBSTITUTE(SUBSTITUTE(SUBSTITUTE(CLEAN(I8&"")," ",""),".","")," ",""),"-",""),FALSE)),SUBSTITUTE(SUBSTITUTE(SUBSTITUTE(SUBSTITUTE(CLEAN(I8&"")," ",""),".","")," ",""),"-",""),"CHECK: not 2, 4, 6, 8 or 10 digits")) | V8: =IF(TRIM(CLEAN(SUBSTITUTE(P8&""," "," ")))="","",UPPER(TRIM(CLEAN(SUBSTITUTE(P8&""," "," "))))&"/"&UPPER(TRIM(CLEAN(SUBSTITUTE(Q8&""," "," "))))) | W8: =IF(V8="","",IF(UPPER(TRIM(CLEAN(SUBSTITUTE(Q8&""," "," "))))<>UPPER(TRIM(CLEAN(SUBSTITUTE(act_Country&""," "," ")))),"CHECK: import country must match B7",IF(COUNTIF(det_Key,V8)>1,"CHECK: listed twice",IF(AND(UPPER(TRIM(CLEAN(SUBSTITUTE(R8&""," "," "))))<>"",UPPER(TRIM(CLEAN(SUBSTITUTE(R8&""," "," "))))<>"IN",UPPER(TRIM(CLEAN(SUBSTITUTE(R8&""," "," "))))<>"OUT"),"CHECK: determination must be IN, OUT or blank",IF(AND(S8&""<>"",NOT(ISNUMBER(S8))),"CHECK: displaced rate must be a percentage",IF(AND(UPPER(TRIM(CLEAN(SUBSTITUTE(R8&""," "," "))))="",NOT(ISNUMBER(S8))),"CHECK: enter IN, OUT or a displaced rate",IF(SUMPRODUCT(--(Calc!$AL$5:$AL$254<>""))=0,"WAIT: Items not loaded yet",IF(COUNTIF(Calc!$AL$5:$AL$254,V8)=0,"CHECK: no Items row for this item and import country","OK")))))))) | AH8: =IF(UPPER(TRIM(CLEAN(SUBSTITUTE(Y8&""," "," "))))="","",COUNTIFS(Calc!$O$5:$O$254,UPPER(TRIM(CLEAN(SUBSTITUTE(Y8&""," "," ")))),Calc!$L$5:$L$254,"Y")) | AI8: =IF(AND(UPPER(TRIM(CLEAN(SUBSTITUTE(Y8&""," "," "))))="",UPPER(TRIM(CLEAN(SUBSTITUTE(Z8&""," "," "))))="",UPPER(TRIM(CLEAN(SUBSTITUTE(AA8&""," "," "))))="",UPPER(TRIM(CLEAN(SUBSTITUTE(AB8&""," "," "))))="",UPPER(TRIM(CLEAN(SUBSTITUTE(AE8&""," "," "))))="",AC8&""="",AD8&""="",AF8&""=""),"",IF(UPPER(TRIM(CLEAN(SUBSTITUTE(Y8&""," "," "))))="","CHECK: line ID missing",IF(NOT(ISNUMBER(AC8)),"CHECK: rate missing",IF(OR(AC8<0,AC8>10),"CHECK: rate must be 0% to 1000%",IF(SUMPRODUCT(--(UPPER(TRIM(CLEAN(SUBSTITUTE(rate_ID&""," "," "))))=UPPER(TRIM(CLEAN(SUBSTITUTE(Y8&""," "," "))))))>1,"CHECK: line ID listed twice",IF(AND(UPPER(TRIM(CLEAN(SUBSTITUTE(Z8&""," "," "))))<>"",SUMPRODUCT(--(UPPER(TRIM(CLEAN(SUBSTITUTE(scope_Group&""," "," "))))=UPPER(TRIM(CLEAN(SUBSTITUTE(Z8&""," "," "))))))=0),"CHECK: rate group not on the scope list",IF(AND(UPPER(TRIM(CLEAN(SUBSTITUTE(AA8&""," "," "))))<>"",SUMPRODUCT(--(UPPER(TRIM(CLEAN(SUBSTITUTE(scope_COO&""," "," "))))=UPPER(TRIM(CLEAN(SUBSTITUTE(AA8&""," "," "))))))=0),"CHECK: origin not on the origin list",IF(AND(UPPER(TRIM(CLEAN(SUBSTITUTE(AB8&""," "," "))))<>"",UPPER(TRIM(CLEAN(SUBSTITUTE(AB8&""," "," "))))<>"Y",UPPER(TRIM(CLEAN(SUBSTITUTE(AB8&""," "," "))))<>"N"),"CHECK: USMCA must be Y, N or blank",IF(AND(UPPER(TRIM(CLEAN(SUBSTITUTE(AE8&""," "," "))))<>"",UPPER(TRIM(CLEAN(SUBSTITUTE(AE8&""," "," "))))<>"FULL",UPPER(TRIM(CLEAN(SUBSTITUTE(AE8&""," "," "))))<>"PART"),"CHECK: duty base must be FULL, PART or blank",IF(OR(AND(AD8&""<>"",NOT(ISNUMBER(AD8))),AND(AF8&""<>"",NOT(ISNUMBER(AF8)))),"CHECK: earlier or displaced rate must be a percentage",IF(AC8>1,"NOTE: rate above 100%: check it was entered as a percentage","OK")))))))))))
A9: Tariff-Impact Brief ID and version | B9: TIB-TA-US-FIC-01 v1.0 | C9: Brief Part 1. The model must match a checked brief version. | F9: =IF(SUBSTITUTE(SUBSTITUTE(SUBSTITUTE(SUBSTITUTE(CLEAN(E9&"")," ",""),".","")," ",""),"-","")="","",IF(AND(OR(LEN(SUBSTITUTE(SUBSTITUTE(SUBSTITUTE(SUBSTITUTE(CLEAN(E9&"")," ",""),".","")," ",""),"-",""))=2,LEN(SUBSTITUTE(SUBSTITUTE(SUBSTITUTE(SUBSTITUTE(CLEAN(E9&"")," ",""),".","")," ",""),"-",""))=4,LEN(SUBSTITUTE(SUBSTITUTE(SUBSTITUTE(SUBSTITUTE(CLEAN(E9&"")," ",""),".","")," ",""),"-",""))=6,LEN(SUBSTITUTE(SUBSTITUTE(SUBSTITUTE(SUBSTITUTE(CLEAN(E9&"")," ",""),".","")," ",""),"-",""))=8,LEN(SUBSTITUTE(SUBSTITUTE(SUBSTITUTE(SUBSTITUTE(CLEAN(E9&"")," ",""),".","")," ",""),"-",""))=10),IFERROR(TEXT(VALUE(SUBSTITUTE(SUBSTITUTE(SUBSTITUTE(SUBSTITUTE(CLEAN(E9&"")," ",""),".","")," ",""),"-","")),REPT("0",LEN(SUBSTITUTE(SUBSTITUTE(SUBSTITUTE(SUBSTITUTE(CLEAN(E9&"")," ",""),".","")," ",""),"-",""))))=SUBSTITUTE(SUBSTITUTE(SUBSTITUTE(SUBSTITUTE(CLEAN(E9&"")," ",""),".","")," ",""),"-",""),FALSE)),SUBSTITUTE(SUBSTITUTE(SUBSTITUTE(SUBSTITUTE(CLEAN(E9&"")," ",""),".","")," ",""),"-",""),"CHECK: not 2, 4, 6, 8 or 10 digits")) | J9: =IF(SUBSTITUTE(SUBSTITUTE(SUBSTITUTE(SUBSTITUTE(CLEAN(I9&"")," ",""),".","")," ",""),"-","")="","",IF(AND(OR(LEN(SUBSTITUTE(SUBSTITUTE(SUBSTITUTE(SUBSTITUTE(CLEAN(I9&"")," ",""),".","")," ",""),"-",""))=2,LEN(SUBSTITUTE(SUBSTITUTE(SUBSTITUTE(SUBSTITUTE(CLEAN(I9&"")," ",""),".","")," ",""),"-",""))=4,LEN(SUBSTITUTE(SUBSTITUTE(SUBSTITUTE(SUBSTITUTE(CLEAN(I9&"")," ",""),".","")," ",""),"-",""))=6,LEN(SUBSTITUTE(SUBSTITUTE(SUBSTITUTE(SUBSTITUTE(CLEAN(I9&"")," ",""),".","")," ",""),"-",""))=8,LEN(SUBSTITUTE(SUBSTITUTE(SUBSTITUTE(SUBSTITUTE(CLEAN(I9&"")," ",""),".","")," ",""),"-",""))=10),IFERROR(TEXT(VALUE(SUBSTITUTE(SUBSTITUTE(SUBSTITUTE(SUBSTITUTE(CLEAN(I9&"")," ",""),".","")," ",""),"-","")),REPT("0",LEN(SUBSTITUTE(SUBSTITUTE(SUBSTITUTE(SUBSTITUTE(CLEAN(I9&"")," ",""),".","")," ",""),"-",""))))=SUBSTITUTE(SUBSTITUTE(SUBSTITUTE(SUBSTITUTE(CLEAN(I9&"")," ",""),".","")," ",""),"-",""),FALSE)),SUBSTITUTE(SUBSTITUTE(SUBSTITUTE(SUBSTITUTE(CLEAN(I9&"")," ",""),".","")," ",""),"-",""),"CHECK: not 2, 4, 6, 8 or 10 digits")) | V9: =IF(TRIM(CLEAN(SUBSTITUTE(P9&""," "," ")))="","",UPPER(TRIM(CLEAN(SUBSTITUTE(P9&""," "," "))))&"/"&UPPER(TRIM(CLEAN(SUBSTITUTE(Q9&""," "," "))))) | W9: =IF(V9="","",IF(UPPER(TRIM(CLEAN(SUBSTITUTE(Q9&""," "," "))))<>UPPER(TRIM(CLEAN(SUBSTITUTE(act_Country&""," "," ")))),"CHECK: import country must match B7",IF(COUNTIF(det_Key,V9)>1,"CHECK: listed twice",IF(AND(UPPER(TRIM(CLEAN(SUBSTITUTE(R9&""," "," "))))<>"",UPPER(TRIM(CLEAN(SUBSTITUTE(R9&""," "," "))))<>"IN",UPPER(TRIM(CLEAN(SUBSTITUTE(R9&""," "," "))))<>"OUT"),"CHECK: determination must be IN, OUT or blank",IF(AND(S9&""<>"",NOT(ISNUMBER(S9))),"CHECK: displaced rate must be a percentage",IF(AND(UPPER(TRIM(CLEAN(SUBSTITUTE(R9&""," "," "))))="",NOT(ISNUMBER(S9))),"CHECK: enter IN, OUT or a displaced rate",IF(SUMPRODUCT(--(Calc!$AL$5:$AL$254<>""))=0,"WAIT: Items not loaded yet",IF(COUNTIF(Calc!$AL$5:$AL$254,V9)=0,"CHECK: no Items row for this item and import country","OK")))))))) | AH9: =IF(UPPER(TRIM(CLEAN(SUBSTITUTE(Y9&""," "," "))))="","",COUNTIFS(Calc!$O$5:$O$254,UPPER(TRIM(CLEAN(SUBSTITUTE(Y9&""," "," ")))),Calc!$L$5:$L$254,"Y")) | AI9: =IF(AND(UPPER(TRIM(CLEAN(SUBSTITUTE(Y9&""," "," "))))="",UPPER(TRIM(CLEAN(SUBSTITUTE(Z9&""," "," "))))="",UPPER(TRIM(CLEAN(SUBSTITUTE(AA9&""," "," "))))="",UPPER(TRIM(CLEAN(SUBSTITUTE(AB9&""," "," "))))="",UPPER(TRIM(CLEAN(SUBSTITUTE(AE9&""," "," "))))="",AC9&""="",AD9&""="",AF9&""=""),"",IF(UPPER(TRIM(CLEAN(SUBSTITUTE(Y9&""," "," "))))="","CHECK: line ID missing",IF(NOT(ISNUMBER(AC9)),"CHECK: rate missing",IF(OR(AC9<0,AC9>10),"CHECK: rate must be 0% to 1000%",IF(SUMPRODUCT(--(UPPER(TRIM(CLEAN(SUBSTITUTE(rate_ID&""," "," "))))=UPPER(TRIM(CLEAN(SUBSTITUTE(Y9&""," "," "))))))>1,"CHECK: line ID listed twice",IF(AND(UPPER(TRIM(CLEAN(SUBSTITUTE(Z9&""," "," "))))<>"",SUMPRODUCT(--(UPPER(TRIM(CLEAN(SUBSTITUTE(scope_Group&""," "," "))))=UPPER(TRIM(CLEAN(SUBSTITUTE(Z9&""," "," "))))))=0),"CHECK: rate group not on the scope list",IF(AND(UPPER(TRIM(CLEAN(SUBSTITUTE(AA9&""," "," "))))<>"",SUMPRODUCT(--(UPPER(TRIM(CLEAN(SUBSTITUTE(scope_COO&""," "," "))))=UPPER(TRIM(CLEAN(SUBSTITUTE(AA9&""," "," "))))))=0),"CHECK: origin not on the origin list",IF(AND(UPPER(TRIM(CLEAN(SUBSTITUTE(AB9&""," "," "))))<>"",UPPER(TRIM(CLEAN(SUBSTITUTE(AB9&""," "," "))))<>"Y",UPPER(TRIM(CLEAN(SUBSTITUTE(AB9&""," "," "))))<>"N"),"CHECK: USMCA must be Y, N or blank",IF(AND(UPPER(TRIM(CLEAN(SUBSTITUTE(AE9&""," "," "))))<>"",UPPER(TRIM(CLEAN(SUBSTITUTE(AE9&""," "," "))))<>"FULL",UPPER(TRIM(CLEAN(SUBSTITUTE(AE9&""," "," "))))<>"PART"),"CHECK: duty base must be FULL, PART or blank",IF(OR(AND(AD9&""<>"",NOT(ISNUMBER(AD9))),AND(AF9&""<>"",NOT(ISNUMBER(AF9)))),"CHECK: earlier or displaced rate must be a percentage",IF(AC9>1,"NOTE: rate above 100%: check it was entered as a percentage","OK")))))))))))
A10: Primary legal source | B10: FICTIONAL: Federal Register notice 92 FR 00000; HTSUS heading 9903.XX.01 | C10: Brief Part 4. Citation of the notice, order or decree. | F10: =IF(SUBSTITUTE(SUBSTITUTE(SUBSTITUTE(SUBSTITUTE(CLEAN(E10&"")," ",""),".","")," ",""),"-","")="","",IF(AND(OR(LEN(SUBSTITUTE(SUBSTITUTE(SUBSTITUTE(SUBSTITUTE(CLEAN(E10&"")," ",""),".","")," ",""),"-",""))=2,LEN(SUBSTITUTE(SUBSTITUTE(SUBSTITUTE(SUBSTITUTE(CLEAN(E10&"")," ",""),".","")," ",""),"-",""))=4,LEN(SUBSTITUTE(SUBSTITUTE(SUBSTITUTE(SUBSTITUTE(CLEAN(E10&"")," ",""),".","")," ",""),"-",""))=6,LEN(SUBSTITUTE(SUBSTITUTE(SUBSTITUTE(SUBSTITUTE(CLEAN(E10&"")," ",""),".","")," ",""),"-",""))=8,LEN(SUBSTITUTE(SUBSTITUTE(SUBSTITUTE(SUBSTITUTE(CLEAN(E10&"")," ",""),".","")," ",""),"-",""))=10),IFERROR(TEXT(VALUE(SUBSTITUTE(SUBSTITUTE(SUBSTITUTE(SUBSTITUTE(CLEAN(E10&"")," ",""),".","")," ",""),"-","")),REPT("0",LEN(SUBSTITUTE(SUBSTITUTE(SUBSTITUTE(SUBSTITUTE(CLEAN(E10&"")," ",""),".","")," ",""),"-",""))))=SUBSTITUTE(SUBSTITUTE(SUBSTITUTE(SUBSTITUTE(CLEAN(E10&"")," ",""),".","")," ",""),"-",""),FALSE)),SUBSTITUTE(SUBSTITUTE(SUBSTITUTE(SUBSTITUTE(CLEAN(E10&"")," ",""),".","")," ",""),"-",""),"CHECK: not 2, 4, 6, 8 or 10 digits")) | J10: =IF(SUBSTITUTE(SUBSTITUTE(SUBSTITUTE(SUBSTITUTE(CLEAN(I10&"")," ",""),".","")," ",""),"-","")="","",IF(AND(OR(LEN(SUBSTITUTE(SUBSTITUTE(SUBSTITUTE(SUBSTITUTE(CLEAN(I10&"")," ",""),".","")," ",""),"-",""))=2,LEN(SUBSTITUTE(SUBSTITUTE(SUBSTITUTE(SUBSTITUTE(CLEAN(I10&"")," ",""),".","")," ",""),"-",""))=4,LEN(SUBSTITUTE(SUBSTITUTE(SUBSTITUTE(SUBSTITUTE(CLEAN(I10&"")," ",""),".","")," ",""),"-",""))=6,LEN(SUBSTITUTE(SUBSTITUTE(SUBSTITUTE(SUBSTITUTE(CLEAN(I10&"")," ",""),".","")," ",""),"-",""))=8,LEN(SUBSTITUTE(SUBSTITUTE(SUBSTITUTE(SUBSTITUTE(CLEAN(I10&"")," ",""),".","")," ",""),"-",""))=10),IFERROR(TEXT(VALUE(SUBSTITUTE(SUBSTITUTE(SUBSTITUTE(SUBSTITUTE(CLEAN(I10&"")," ",""),".","")," ",""),"-","")),REPT("0",LEN(SUBSTITUTE(SUBSTITUTE(SUBSTITUTE(SUBSTITUTE(CLEAN(I10&"")," ",""),".","")," ",""),"-",""))))=SUBSTITUTE(SUBSTITUTE(SUBSTITUTE(SUBSTITUTE(CLEAN(I10&"")," ",""),".","")," ",""),"-",""),FALSE)),SUBSTITUTE(SUBSTITUTE(SUBSTITUTE(SUBSTITUTE(CLEAN(I10&"")," ",""),".","")," ",""),"-",""),"CHECK: not 2, 4, 6, 8 or 10 digits")) | V10: =IF(TRIM(CLEAN(SUBSTITUTE(P10&""," "," ")))="","",UPPER(TRIM(CLEAN(SUBSTITUTE(P10&""," "," "))))&"/"&UPPER(TRIM(CLEAN(SUBSTITUTE(Q10&""," "," "))))) | W10: =IF(V10="","",IF(UPPER(TRIM(CLEAN(SUBSTITUTE(Q10&""," "," "))))<>UPPER(TRIM(CLEAN(SUBSTITUTE(act_Country&""," "," ")))),"CHECK: import country must match B7",IF(COUNTIF(det_Key,V10)>1,"CHECK: listed twice",IF(AND(UPPER(TRIM(CLEAN(SUBSTITUTE(R10&""," "," "))))<>"",UPPER(TRIM(CLEAN(SUBSTITUTE(R10&""," "," "))))<>"IN",UPPER(TRIM(CLEAN(SUBSTITUTE(R10&""," "," "))))<>"OUT"),"CHECK: determination must be IN, OUT or blank",IF(AND(S10&""<>"",NOT(ISNUMBER(S10))),"CHECK: displaced rate must be a percentage",IF(AND(UPPER(TRIM(CLEAN(SUBSTITUTE(R10&""," "," "))))="",NOT(ISNUMBER(S10))),"CHECK: enter IN, OUT or a displaced rate",IF(SUMPRODUCT(--(Calc!$AL$5:$AL$254<>""))=0,"WAIT: Items not loaded yet",IF(COUNTIF(Calc!$AL$5:$AL$254,V10)=0,"CHECK: no Items row for this item and import country","OK")))))))) | AH10: =IF(UPPER(TRIM(CLEAN(SUBSTITUTE(Y10&""," "," "))))="","",COUNTIFS(Calc!$O$5:$O$254,UPPER(TRIM(CLEAN(SUBSTITUTE(Y10&""," "," ")))),Calc!$L$5:$L$254,"Y")) | AI10: =IF(AND(UPPER(TRIM(CLEAN(SUBSTITUTE(Y10&""," "," "))))="",UPPER(TRIM(CLEAN(SUBSTITUTE(Z10&""," "," "))))="",UPPER(TRIM(CLEAN(SUBSTITUTE(AA10&""," "," "))))="",UPPER(TRIM(CLEAN(SUBSTITUTE(AB10&""," "," "))))="",UPPER(TRIM(CLEAN(SUBSTITUTE(AE10&""," "," "))))="",AC10&""="",AD10&""="",AF10&""=""),"",IF(UPPER(TRIM(CLEAN(SUBSTITUTE(Y10&""," "," "))))="","CHECK: line ID missing",IF(NOT(ISNUMBER(AC10)),"CHECK: rate missing",IF(OR(AC10<0,AC10>10),"CHECK: rate must be 0% to 1000%",IF(SUMPRODUCT(--(UPPER(TRIM(CLEAN(SUBSTITUTE(rate_ID&""," "," "))))=UPPER(TRIM(CLEAN(SUBSTITUTE(Y10&""," "," "))))))>1,"CHECK: line ID listed twice",IF(AND(UPPER(TRIM(CLEAN(SUBSTITUTE(Z10&""," "," "))))<>"",SUMPRODUCT(--(UPPER(TRIM(CLEAN(SUBSTITUTE(scope_Group&""," "," "))))=UPPER(TRIM(CLEAN(SUBSTITUTE(Z10&""," "," "))))))=0),"CHECK: rate group not on the scope list",IF(AND(UPPER(TRIM(CLEAN(SUBSTITUTE(AA10&""," "," "))))<>"",SUMPRODUCT(--(UPPER(TRIM(CLEAN(SUBSTITUTE(scope_COO&""," "," "))))=UPPER(TRIM(CLEAN(SUBSTITUTE(AA10&""," "," "))))))=0),"CHECK: origin not on the origin list",IF(AND(UPPER(TRIM(CLEAN(SUBSTITUTE(AB10&""," "," "))))<>"",UPPER(TRIM(CLEAN(SUBSTITUTE(AB10&""," "," "))))<>"Y",UPPER(TRIM(CLEAN(SUBSTITUTE(AB10&""," "," "))))<>"N"),"CHECK: USMCA must be Y, N or blank",IF(AND(UPPER(TRIM(CLEAN(SUBSTITUTE(AE10&""," "," "))))<>"",UPPER(TRIM(CLEAN(SUBSTITUTE(AE10&""," "," "))))<>"FULL",UPPER(TRIM(CLEAN(SUBSTITUTE(AE10&""," "," "))))<>"PART"),"CHECK: duty base must be FULL, PART or blank",IF(OR(AND(AD10&""<>"",NOT(ISNUMBER(AD10))),AND(AF10&""<>"",NOT(ISNUMBER(AF10)))),"CHECK: earlier or displaced rate must be a percentage",IF(AC10>1,"NOTE: rate above 100%: check it was entered as a percentage","OK")))))))))))
A11: Effective date | B11: 46447 | C11: Brief Part 5. Shown on the Summary; not applied by the formulas. | F11: =IF(SUBSTITUTE(SUBSTITUTE(SUBSTITUTE(SUBSTITUTE(CLEAN(E11&"")," ",""),".","")," ",""),"-","")="","",IF(AND(OR(LEN(SUBSTITUTE(SUBSTITUTE(SUBSTITUTE(SUBSTITUTE(CLEAN(E11&"")," ",""),".","")," ",""),"-",""))=2,LEN(SUBSTITUTE(SUBSTITUTE(SUBSTITUTE(SUBSTITUTE(CLEAN(E11&"")," ",""),".","")," ",""),"-",""))=4,LEN(SUBSTITUTE(SUBSTITUTE(SUBSTITUTE(SUBSTITUTE(CLEAN(E11&"")," ",""),".","")," ",""),"-",""))=6,LEN(SUBSTITUTE(SUBSTITUTE(SUBSTITUTE(SUBSTITUTE(CLEAN(E11&"")," ",""),".","")," ",""),"-",""))=8,LEN(SUBSTITUTE(SUBSTITUTE(SUBSTITUTE(SUBSTITUTE(CLEAN(E11&"")," ",""),".","")," ",""),"-",""))=10),IFERROR(TEXT(VALUE(SUBSTITUTE(SUBSTITUTE(SUBSTITUTE(SUBSTITUTE(CLEAN(E11&"")," ",""),".","")," ",""),"-","")),REPT("0",LEN(SUBSTITUTE(SUBSTITUTE(SUBSTITUTE(SUBSTITUTE(CLEAN(E11&"")," ",""),".","")," ",""),"-",""))))=SUBSTITUTE(SUBSTITUTE(SUBSTITUTE(SUBSTITUTE(CLEAN(E11&"")," ",""),".","")," ",""),"-",""),FALSE)),SUBSTITUTE(SUBSTITUTE(SUBSTITUTE(SUBSTITUTE(CLEAN(E11&"")," ",""),".","")," ",""),"-",""),"CHECK: not 2, 4, 6, 8 or 10 digits")) | J11: =IF(SUBSTITUTE(SUBSTITUTE(SUBSTITUTE(SUBSTITUTE(CLEAN(I11&"")," ",""),".","")," ",""),"-","")="","",IF(AND(OR(LEN(SUBSTITUTE(SUBSTITUTE(SUBSTITUTE(SUBSTITUTE(CLEAN(I11&"")," ",""),".","")," ",""),"-",""))=2,LEN(SUBSTITUTE(SUBSTITUTE(SUBSTITUTE(SUBSTITUTE(CLEAN(I11&"")," ",""),".","")," ",""),"-",""))=4,LEN(SUBSTITUTE(SUBSTITUTE(SUBSTITUTE(SUBSTITUTE(CLEAN(I11&"")," ",""),".","")," ",""),"-",""))=6,LEN(SUBSTITUTE(SUBSTITUTE(SUBSTITUTE(SUBSTITUTE(CLEAN(I11&"")," ",""),".","")," ",""),"-",""))=8,LEN(SUBSTITUTE(SUBSTITUTE(SUBSTITUTE(SUBSTITUTE(CLEAN(I11&"")," ",""),".","")," ",""),"-",""))=10),IFERROR(TEXT(VALUE(SUBSTITUTE(SUBSTITUTE(SUBSTITUTE(SUBSTITUTE(CLEAN(I11&"")," ",""),".","")," ",""),"-","")),REPT("0",LEN(SUBSTITUTE(SUBSTITUTE(SUBSTITUTE(SUBSTITUTE(CLEAN(I11&"")," ",""),".","")," ",""),"-",""))))=SUBSTITUTE(SUBSTITUTE(SUBSTITUTE(SUBSTITUTE(CLEAN(I11&"")," ",""),".","")," ",""),"-",""),FALSE)),SUBSTITUTE(SUBSTITUTE(SUBSTITUTE(SUBSTITUTE(CLEAN(I11&"")," ",""),".","")," ",""),"-",""),"CHECK: not 2, 4, 6, 8 or 10 digits")) | V11: =IF(TRIM(CLEAN(SUBSTITUTE(P11&""," "," ")))="","",UPPER(TRIM(CLEAN(SUBSTITUTE(P11&""," "," "))))&"/"&UPPER(TRIM(CLEAN(SUBSTITUTE(Q11&""," "," "))))) | W11: =IF(V11="","",IF(UPPER(TRIM(CLEAN(SUBSTITUTE(Q11&""," "," "))))<>UPPER(TRIM(CLEAN(SUBSTITUTE(act_Country&""," "," ")))),"CHECK: import country must match B7",IF(COUNTIF(det_Key,V11)>1,"CHECK: listed twice",IF(AND(UPPER(TRIM(CLEAN(SUBSTITUTE(R11&""," "," "))))<>"",UPPER(TRIM(CLEAN(SUBSTITUTE(R11&""," "," "))))<>"IN",UPPER(TRIM(CLEAN(SUBSTITUTE(R11&""," "," "))))<>"OUT"),"CHECK: determination must be IN, OUT or blank",IF(AND(S11&""<>"",NOT(ISNUMBER(S11))),"CHECK: displaced rate must be a percentage",IF(AND(UPPER(TRIM(CLEAN(SUBSTITUTE(R11&""," "," "))))="",NOT(ISNUMBER(S11))),"CHECK: enter IN, OUT or a displaced rate",IF(SUMPRODUCT(--(Calc!$AL$5:$AL$254<>""))=0,"WAIT: Items not loaded yet",IF(COUNTIF(Calc!$AL$5:$AL$254,V11)=0,"CHECK: no Items row for this item and import country","OK")))))))) | AH11: =IF(UPPER(TRIM(CLEAN(SUBSTITUTE(Y11&""," "," "))))="","",COUNTIFS(Calc!$O$5:$O$254,UPPER(TRIM(CLEAN(SUBSTITUTE(Y11&""," "," ")))),Calc!$L$5:$L$254,"Y")) | AI11: =IF(AND(UPPER(TRIM(CLEAN(SUBSTITUTE(Y11&""," "," "))))="",UPPER(TRIM(CLEAN(SUBSTITUTE(Z11&""," "," "))))="",UPPER(TRIM(CLEAN(SUBSTITUTE(AA11&""," "," "))))="",UPPER(TRIM(CLEAN(SUBSTITUTE(AB11&""," "," "))))="",UPPER(TRIM(CLEAN(SUBSTITUTE(AE11&""," "," "))))="",AC11&""="",AD11&""="",AF11&""=""),"",IF(UPPER(TRIM(CLEAN(SUBSTITUTE(Y11&""," "," "))))="","CHECK: line ID missing",IF(NOT(ISNUMBER(AC11)),"CHECK: rate missing",IF(OR(AC11<0,AC11>10),"CHECK: rate must be 0% to 1000%",IF(SUMPRODUCT(--(UPPER(TRIM(CLEAN(SUBSTITUTE(rate_ID&""," "," "))))=UPPER(TRIM(CLEAN(SUBSTITUTE(Y11&""," "," "))))))>1,"CHECK: line ID listed twice",IF(AND(UPPER(TRIM(CLEAN(SUBSTITUTE(Z11&""," "," "))))<>"",SUMPRODUCT(--(UPPER(TRIM(CLEAN(SUBSTITUTE(scope_Group&""," "," "))))=UPPER(TRIM(CLEAN(SUBSTITUTE(Z11&""," "," "))))))=0),"CHECK: rate group not on the scope list",IF(AND(UPPER(TRIM(CLEAN(SUBSTITUTE(AA11&""," "," "))))<>"",SUMPRODUCT(--(UPPER(TRIM(CLEAN(SUBSTITUTE(scope_COO&""," "," "))))=UPPER(TRIM(CLEAN(SUBSTITUTE(AA11&""," "," "))))))=0),"CHECK: origin not on the origin list",IF(AND(UPPER(TRIM(CLEAN(SUBSTITUTE(AB11&""," "," "))))<>"",UPPER(TRIM(CLEAN(SUBSTITUTE(AB11&""," "," "))))<>"Y",UPPER(TRIM(CLEAN(SUBSTITUTE(AB11&""," "," "))))<>"N"),"CHECK: USMCA must be Y, N or blank",IF(AND(UPPER(TRIM(CLEAN(SUBSTITUTE(AE11&""," "," "))))<>"",UPPER(TRIM(CLEAN(SUBSTITUTE(AE11&""," "," "))))<>"FULL",UPPER(TRIM(CLEAN(SUBSTITUTE(AE11&""," "," "))))<>"PART"),"CHECK: duty base must be FULL, PART or blank",IF(OR(AND(AD11&""<>"",NOT(ISNUMBER(AD11))),AND(AF11&""<>"",NOT(ISNUMBER(AF11)))),"CHECK: earlier or displaced rate must be a percentage",IF(AC11>1,"NOTE: rate above 100%: check it was entered as a percentage","OK")))))))))))
A12: Effective time and basis | B12: 12:01 a.m. ET; goods entered for consumption, or withdrawn from warehouse for consumption, on or after the effective date | C12: Brief Part 5. Quote the notice wording. | F12: =IF(SUBSTITUTE(SUBSTITUTE(SUBSTITUTE(SUBSTITUTE(CLEAN(E12&"")," ",""),".","")," ",""),"-","")="","",IF(AND(OR(LEN(SUBSTITUTE(SUBSTITUTE(SUBSTITUTE(SUBSTITUTE(CLEAN(E12&"")," ",""),".","")," ",""),"-",""))=2,LEN(SUBSTITUTE(SUBSTITUTE(SUBSTITUTE(SUBSTITUTE(CLEAN(E12&"")," ",""),".","")," ",""),"-",""))=4,LEN(SUBSTITUTE(SUBSTITUTE(SUBSTITUTE(SUBSTITUTE(CLEAN(E12&"")," ",""),".","")," ",""),"-",""))=6,LEN(SUBSTITUTE(SUBSTITUTE(SUBSTITUTE(SUBSTITUTE(CLEAN(E12&"")," ",""),".","")," ",""),"-",""))=8,LEN(SUBSTITUTE(SUBSTITUTE(SUBSTITUTE(SUBSTITUTE(CLEAN(E12&"")," ",""),".","")," ",""),"-",""))=10),IFERROR(TEXT(VALUE(SUBSTITUTE(SUBSTITUTE(SUBSTITUTE(SUBSTITUTE(CLEAN(E12&"")," ",""),".","")," ",""),"-","")),REPT("0",LEN(SUBSTITUTE(SUBSTITUTE(SUBSTITUTE(SUBSTITUTE(CLEAN(E12&"")," ",""),".","")," ",""),"-",""))))=SUBSTITUTE(SUBSTITUTE(SUBSTITUTE(SUBSTITUTE(CLEAN(E12&"")," ",""),".","")," ",""),"-",""),FALSE)),SUBSTITUTE(SUBSTITUTE(SUBSTITUTE(SUBSTITUTE(CLEAN(E12&"")," ",""),".","")," ",""),"-",""),"CHECK: not 2, 4, 6, 8 or 10 digits")) | J12: =IF(SUBSTITUTE(SUBSTITUTE(SUBSTITUTE(SUBSTITUTE(CLEAN(I12&"")," ",""),".","")," ",""),"-","")="","",IF(AND(OR(LEN(SUBSTITUTE(SUBSTITUTE(SUBSTITUTE(SUBSTITUTE(CLEAN(I12&"")," ",""),".","")," ",""),"-",""))=2,LEN(SUBSTITUTE(SUBSTITUTE(SUBSTITUTE(SUBSTITUTE(CLEAN(I12&"")," ",""),".","")," ",""),"-",""))=4,LEN(SUBSTITUTE(SUBSTITUTE(SUBSTITUTE(SUBSTITUTE(CLEAN(I12&"")," ",""),".","")," ",""),"-",""))=6,LEN(SUBSTITUTE(SUBSTITUTE(SUBSTITUTE(SUBSTITUTE(CLEAN(I12&"")," ",""),".","")," ",""),"-",""))=8,LEN(SUBSTITUTE(SUBSTITUTE(SUBSTITUTE(SUBSTITUTE(CLEAN(I12&"")," ",""),".","")," ",""),"-",""))=10),IFERROR(TEXT(VALUE(SUBSTITUTE(SUBSTITUTE(SUBSTITUTE(SUBSTITUTE(CLEAN(I12&"")," ",""),".","")," ",""),"-","")),REPT("0",LEN(SUBSTITUTE(SUBSTITUTE(SUBSTITUTE(SUBSTITUTE(CLEAN(I12&"")," ",""),".","")," ",""),"-",""))))=SUBSTITUTE(SUBSTITUTE(SUBSTITUTE(SUBSTITUTE(CLEAN(I12&"")," ",""),".","")," ",""),"-",""),FALSE)),SUBSTITUTE(SUBSTITUTE(SUBSTITUTE(SUBSTITUTE(CLEAN(I12&"")," ",""),".","")," ",""),"-",""),"CHECK: not 2, 4, 6, 8 or 10 digits")) | V12: =IF(TRIM(CLEAN(SUBSTITUTE(P12&""," "," ")))="","",UPPER(TRIM(CLEAN(SUBSTITUTE(P12&""," "," "))))&"/"&UPPER(TRIM(CLEAN(SUBSTITUTE(Q12&""," "," "))))) | W12: =IF(V12="","",IF(UPPER(TRIM(CLEAN(SUBSTITUTE(Q12&""," "," "))))<>UPPER(TRIM(CLEAN(SUBSTITUTE(act_Country&""," "," ")))),"CHECK: import country must match B7",IF(COUNTIF(det_Key,V12)>1,"CHECK: listed twice",IF(AND(UPPER(TRIM(CLEAN(SUBSTITUTE(R12&""," "," "))))<>"",UPPER(TRIM(CLEAN(SUBSTITUTE(R12&""," "," "))))<>"IN",UPPER(TRIM(CLEAN(SUBSTITUTE(R12&""," "," "))))<>"OUT"),"CHECK: determination must be IN, OUT or blank",IF(AND(S12&""<>"",NOT(ISNUMBER(S12))),"CHECK: displaced rate must be a percentage",IF(AND(UPPER(TRIM(CLEAN(SUBSTITUTE(R12&""," "," "))))="",NOT(ISNUMBER(S12))),"CHECK: enter IN, OUT or a displaced rate",IF(SUMPRODUCT(--(Calc!$AL$5:$AL$254<>""))=0,"WAIT: Items not loaded yet",IF(COUNTIF(Calc!$AL$5:$AL$254,V12)=0,"CHECK: no Items row for this item and import country","OK")))))))) | AH12: =IF(UPPER(TRIM(CLEAN(SUBSTITUTE(Y12&""," "," "))))="","",COUNTIFS(Calc!$O$5:$O$254,UPPER(TRIM(CLEAN(SUBSTITUTE(Y12&""," "," ")))),Calc!$L$5:$L$254,"Y")) | AI12: =IF(AND(UPPER(TRIM(CLEAN(SUBSTITUTE(Y12&""," "," "))))="",UPPER(TRIM(CLEAN(SUBSTITUTE(Z12&""," "," "))))="",UPPER(TRIM(CLEAN(SUBSTITUTE(AA12&""," "," "))))="",UPPER(TRIM(CLEAN(SUBSTITUTE(AB12&""," "," "))))="",UPPER(TRIM(CLEAN(SUBSTITUTE(AE12&""," "," "))))="",AC12&""="",AD12&""="",AF12&""=""),"",IF(UPPER(TRIM(CLEAN(SUBSTITUTE(Y12&""," "," "))))="","CHECK: line ID missing",IF(NOT(ISNUMBER(AC12)),"CHECK: rate missing",IF(OR(AC12<0,AC12>10),"CHECK: rate must be 0% to 1000%",IF(SUMPRODUCT(--(UPPER(TRIM(CLEAN(SUBSTITUTE(rate_ID&""," "," "))))=UPPER(TRIM(CLEAN(SUBSTITUTE(Y12&""," "," "))))))>1,"CHECK: line ID listed twice",IF(AND(UPPER(TRIM(CLEAN(SUBSTITUTE(Z12&""," "," "))))<>"",SUMPRODUCT(--(UPPER(TRIM(CLEAN(SUBSTITUTE(scope_Group&""," "," "))))=UPPER(TRIM(CLEAN(SUBSTITUTE(Z12&""," "," "))))))=0),"CHECK: rate group not on the scope list",IF(AND(UPPER(TRIM(CLEAN(SUBSTITUTE(AA12&""," "," "))))<>"",SUMPRODUCT(--(UPPER(TRIM(CLEAN(SUBSTITUTE(scope_COO&""," "," "))))=UPPER(TRIM(CLEAN(SUBSTITUTE(AA12&""," "," "))))))=0),"CHECK: origin not on the origin list",IF(AND(UPPER(TRIM(CLEAN(SUBSTITUTE(AB12&""," "," "))))<>"",UPPER(TRIM(CLEAN(SUBSTITUTE(AB12&""," "," "))))<>"Y",UPPER(TRIM(CLEAN(SUBSTITUTE(AB12&""," "," "))))<>"N"),"CHECK: USMCA must be Y, N or blank",IF(AND(UPPER(TRIM(CLEAN(SUBSTITUTE(AE12&""," "," "))))<>"",UPPER(TRIM(CLEAN(SUBSTITUTE(AE12&""," "," "))))<>"FULL",UPPER(TRIM(CLEAN(SUBSTITUTE(AE12&""," "," "))))<>"PART"),"CHECK: duty base must be FULL, PART or blank",IF(OR(AND(AD12&""<>"",NOT(ISNUMBER(AD12))),AND(AF12&""<>"",NOT(ISNUMBER(AF12)))),"CHECK: earlier or displaced rate must be a percentage",IF(AC12>1,"NOTE: rate above 100%: check it was entered as a percentage","OK")))))))))))
A13: In-transit provision | B13: FICTIONAL: not covered if loaded on the final mode of transit before the effective date and entered before 2027-04-30 | C13: Brief Part 5. Not applied by the formulas; Standard Cost handles in-transit stock separately. | F13: =IF(SUBSTITUTE(SUBSTITUTE(SUBSTITUTE(SUBSTITUTE(CLEAN(E13&"")," ",""),".","")," ",""),"-","")="","",IF(AND(OR(LEN(SUBSTITUTE(SUBSTITUTE(SUBSTITUTE(SUBSTITUTE(CLEAN(E13&"")," ",""),".","")," ",""),"-",""))=2,LEN(SUBSTITUTE(SUBSTITUTE(SUBSTITUTE(SUBSTITUTE(CLEAN(E13&"")," ",""),".","")," ",""),"-",""))=4,LEN(SUBSTITUTE(SUBSTITUTE(SUBSTITUTE(SUBSTITUTE(CLEAN(E13&"")," ",""),".","")," ",""),"-",""))=6,LEN(SUBSTITUTE(SUBSTITUTE(SUBSTITUTE(SUBSTITUTE(CLEAN(E13&"")," ",""),".","")," ",""),"-",""))=8,LEN(SUBSTITUTE(SUBSTITUTE(SUBSTITUTE(SUBSTITUTE(CLEAN(E13&"")," ",""),".","")," ",""),"-",""))=10),IFERROR(TEXT(VALUE(SUBSTITUTE(SUBSTITUTE(SUBSTITUTE(SUBSTITUTE(CLEAN(E13&"")," ",""),".","")," ",""),"-","")),REPT("0",LEN(SUBSTITUTE(SUBSTITUTE(SUBSTITUTE(SUBSTITUTE(CLEAN(E13&"")," ",""),".","")," ",""),"-",""))))=SUBSTITUTE(SUBSTITUTE(SUBSTITUTE(SUBSTITUTE(CLEAN(E13&"")," ",""),".","")," ",""),"-",""),FALSE)),SUBSTITUTE(SUBSTITUTE(SUBSTITUTE(SUBSTITUTE(CLEAN(E13&"")," ",""),".","")," ",""),"-",""),"CHECK: not 2, 4, 6, 8 or 10 digits")) | J13: =IF(SUBSTITUTE(SUBSTITUTE(SUBSTITUTE(SUBSTITUTE(CLEAN(I13&"")," ",""),".","")," ",""),"-","")="","",IF(AND(OR(LEN(SUBSTITUTE(SUBSTITUTE(SUBSTITUTE(SUBSTITUTE(CLEAN(I13&"")," ",""),".","")," ",""),"-",""))=2,LEN(SUBSTITUTE(SUBSTITUTE(SUBSTITUTE(SUBSTITUTE(CLEAN(I13&"")," ",""),".","")," ",""),"-",""))=4,LEN(SUBSTITUTE(SUBSTITUTE(SUBSTITUTE(SUBSTITUTE(CLEAN(I13&"")," ",""),".","")," ",""),"-",""))=6,LEN(SUBSTITUTE(SUBSTITUTE(SUBSTITUTE(SUBSTITUTE(CLEAN(I13&"")," ",""),".","")," ",""),"-",""))=8,LEN(SUBSTITUTE(SUBSTITUTE(SUBSTITUTE(SUBSTITUTE(CLEAN(I13&"")," ",""),".","")," ",""),"-",""))=10),IFERROR(TEXT(VALUE(SUBSTITUTE(SUBSTITUTE(SUBSTITUTE(SUBSTITUTE(CLEAN(I13&"")," ",""),".","")," ",""),"-","")),REPT("0",LEN(SUBSTITUTE(SUBSTITUTE(SUBSTITUTE(SUBSTITUTE(CLEAN(I13&"")," ",""),".","")," ",""),"-",""))))=SUBSTITUTE(SUBSTITUTE(SUBSTITUTE(SUBSTITUTE(CLEAN(I13&"")," ",""),".","")," ",""),"-",""),FALSE)),SUBSTITUTE(SUBSTITUTE(SUBSTITUTE(SUBSTITUTE(CLEAN(I13&"")," ",""),".","")," ",""),"-",""),"CHECK: not 2, 4, 6, 8 or 10 digits")) | V13: =IF(TRIM(CLEAN(SUBSTITUTE(P13&""," "," ")))="","",UPPER(TRIM(CLEAN(SUBSTITUTE(P13&""," "," "))))&"/"&UPPER(TRIM(CLEAN(SUBSTITUTE(Q13&""," "," "))))) | W13: =IF(V13="","",IF(UPPER(TRIM(CLEAN(SUBSTITUTE(Q13&""," "," "))))<>UPPER(TRIM(CLEAN(SUBSTITUTE(act_Country&""," "," ")))),"CHECK: import country must match B7",IF(COUNTIF(det_Key,V13)>1,"CHECK: listed twice",IF(AND(UPPER(TRIM(CLEAN(SUBSTITUTE(R13&""," "," "))))<>"",UPPER(TRIM(CLEAN(SUBSTITUTE(R13&""," "," "))))<>"IN",UPPER(TRIM(CLEAN(SUBSTITUTE(R13&""," "," "))))<>"OUT"),"CHECK: determination must be IN, OUT or blank",IF(AND(S13&""<>"",NOT(ISNUMBER(S13))),"CHECK: displaced rate must be a percentage",IF(AND(UPPER(TRIM(CLEAN(SUBSTITUTE(R13&""," "," "))))="",NOT(ISNUMBER(S13))),"CHECK: enter IN, OUT or a displaced rate",IF(SUMPRODUCT(--(Calc!$AL$5:$AL$254<>""))=0,"WAIT: Items not loaded yet",IF(COUNTIF(Calc!$AL$5:$AL$254,V13)=0,"CHECK: no Items row for this item and import country","OK")))))))) | AH13: =IF(UPPER(TRIM(CLEAN(SUBSTITUTE(Y13&""," "," "))))="","",COUNTIFS(Calc!$O$5:$O$254,UPPER(TRIM(CLEAN(SUBSTITUTE(Y13&""," "," ")))),Calc!$L$5:$L$254,"Y")) | AI13: =IF(AND(UPPER(TRIM(CLEAN(SUBSTITUTE(Y13&""," "," "))))="",UPPER(TRIM(CLEAN(SUBSTITUTE(Z13&""," "," "))))="",UPPER(TRIM(CLEAN(SUBSTITUTE(AA13&""," "," "))))="",UPPER(TRIM(CLEAN(SUBSTITUTE(AB13&""," "," "))))="",UPPER(TRIM(CLEAN(SUBSTITUTE(AE13&""," "," "))))="",AC13&""="",AD13&""="",AF13&""=""),"",IF(UPPER(TRIM(CLEAN(SUBSTITUTE(Y13&""," "," "))))="","CHECK: line ID missing",IF(NOT(ISNUMBER(AC13)),"CHECK: rate missing",IF(OR(AC13<0,AC13>10),"CHECK: rate must be 0% to 1000%",IF(SUMPRODUCT(--(UPPER(TRIM(CLEAN(SUBSTITUTE(rate_ID&""," "," "))))=UPPER(TRIM(CLEAN(SUBSTITUTE(Y13&""," "," "))))))>1,"CHECK: line ID listed twice",IF(AND(UPPER(TRIM(CLEAN(SUBSTITUTE(Z13&""," "," "))))<>"",SUMPRODUCT(--(UPPER(TRIM(CLEAN(SUBSTITUTE(scope_Group&""," "," "))))=UPPER(TRIM(CLEAN(SUBSTITUTE(Z13&""," "," "))))))=0),"CHECK: rate group not on the scope list",IF(AND(UPPER(TRIM(CLEAN(SUBSTITUTE(AA13&""," "," "))))<>"",SUMPRODUCT(--(UPPER(TRIM(CLEAN(SUBSTITUTE(scope_COO&""," "," "))))=UPPER(TRIM(CLEAN(SUBSTITUTE(AA13&""," "," "))))))=0),"CHECK: origin not on the origin list",IF(AND(UPPER(TRIM(CLEAN(SUBSTITUTE(AB13&""," "," "))))<>"",UPPER(TRIM(CLEAN(SUBSTITUTE(AB13&""," "," "))))<>"Y",UPPER(TRIM(CLEAN(SUBSTITUTE(AB13&""," "," "))))<>"N"),"CHECK: USMCA must be Y, N or blank",IF(AND(UPPER(TRIM(CLEAN(SUBSTITUTE(AE13&""," "," "))))<>"",UPPER(TRIM(CLEAN(SUBSTITUTE(AE13&""," "," "))))<>"FULL",UPPER(TRIM(CLEAN(SUBSTITUTE(AE13&""," "," "))))<>"PART"),"CHECK: duty base must be FULL, PART or blank",IF(OR(AND(AD13&""<>"",NOT(ISNUMBER(AD13))),AND(AF13&""<>"",NOT(ISNUMBER(AF13)))),"CHECK: earlier or displaced rate must be a percentage",IF(AC13>1,"NOTE: rate above 100%: check it was entered as a percentage","OK")))))))))))
A14: End date (blank if none) | C14: Brief Part 5. Not applied by the formulas. | F14: =IF(SUBSTITUTE(SUBSTITUTE(SUBSTITUTE(SUBSTITUTE(CLEAN(E14&"")," ",""),".","")," ",""),"-","")="","",IF(AND(OR(LEN(SUBSTITUTE(SUBSTITUTE(SUBSTITUTE(SUBSTITUTE(CLEAN(E14&"")," ",""),".","")," ",""),"-",""))=2,LEN(SUBSTITUTE(SUBSTITUTE(SUBSTITUTE(SUBSTITUTE(CLEAN(E14&"")," ",""),".","")," ",""),"-",""))=4,LEN(SUBSTITUTE(SUBSTITUTE(SUBSTITUTE(SUBSTITUTE(CLEAN(E14&"")," ",""),".","")," ",""),"-",""))=6,LEN(SUBSTITUTE(SUBSTITUTE(SUBSTITUTE(SUBSTITUTE(CLEAN(E14&"")," ",""),".","")," ",""),"-",""))=8,LEN(SUBSTITUTE(SUBSTITUTE(SUBSTITUTE(SUBSTITUTE(CLEAN(E14&"")," ",""),".","")," ",""),"-",""))=10),IFERROR(TEXT(VALUE(SUBSTITUTE(SUBSTITUTE(SUBSTITUTE(SUBSTITUTE(CLEAN(E14&"")," ",""),".","")," ",""),"-","")),REPT("0",LEN(SUBSTITUTE(SUBSTITUTE(SUBSTITUTE(SUBSTITUTE(CLEAN(E14&"")," ",""),".","")," ",""),"-",""))))=SUBSTITUTE(SUBSTITUTE(SUBSTITUTE(SUBSTITUTE(CLEAN(E14&"")," ",""),".","")," ",""),"-",""),FALSE)),SUBSTITUTE(SUBSTITUTE(SUBSTITUTE(SUBSTITUTE(CLEAN(E14&"")," ",""),".","")," ",""),"-",""),"CHECK: not 2, 4, 6, 8 or 10 digits")) | J14: =IF(SUBSTITUTE(SUBSTITUTE(SUBSTITUTE(SUBSTITUTE(CLEAN(I14&"")," ",""),".","")," ",""),"-","")="","",IF(AND(OR(LEN(SUBSTITUTE(SUBSTITUTE(SUBSTITUTE(SUBSTITUTE(CLEAN(I14&"")," ",""),".","")," ",""),"-",""))=2,LEN(SUBSTITUTE(SUBSTITUTE(SUBSTITUTE(SUBSTITUTE(CLEAN(I14&"")," ",""),".","")," ",""),"-",""))=4,LEN(SUBSTITUTE(SUBSTITUTE(SUBSTITUTE(SUBSTITUTE(CLEAN(I14&"")," ",""),".","")," ",""),"-",""))=6,LEN(SUBSTITUTE(SUBSTITUTE(SUBSTITUTE(SUBSTITUTE(CLEAN(I14&"")," ",""),".","")," ",""),"-",""))=8,LEN(SUBSTITUTE(SUBSTITUTE(SUBSTITUTE(SUBSTITUTE(CLEAN(I14&"")," ",""),".","")," ",""),"-",""))=10),IFERROR(TEXT(VALUE(SUBSTITUTE(SUBSTITUTE(SUBSTITUTE(SUBSTITUTE(CLEAN(I14&"")," ",""),".","")," ",""),"-","")),REPT("0",LEN(SUBSTITUTE(SUBSTITUTE(SUBSTITUTE(SUBSTITUTE(CLEAN(I14&"")," ",""),".","")," ",""),"-",""))))=SUBSTITUTE(SUBSTITUTE(SUBSTITUTE(SUBSTITUTE(CLEAN(I14&"")," ",""),".","")," ",""),"-",""),FALSE)),SUBSTITUTE(SUBSTITUTE(SUBSTITUTE(SUBSTITUTE(CLEAN(I14&"")," ",""),".","")," ",""),"-",""),"CHECK: not 2, 4, 6, 8 or 10 digits")) | V14: =IF(TRIM(CLEAN(SUBSTITUTE(P14&""," "," ")))="","",UPPER(TRIM(CLEAN(SUBSTITUTE(P14&""," "," "))))&"/"&UPPER(TRIM(CLEAN(SUBSTITUTE(Q14&""," "," "))))) | W14: =IF(V14="","",IF(UPPER(TRIM(CLEAN(SUBSTITUTE(Q14&""," "," "))))<>UPPER(TRIM(CLEAN(SUBSTITUTE(act_Country&""," "," ")))),"CHECK: import country must match B7",IF(COUNTIF(det_Key,V14)>1,"CHECK: listed twice",IF(AND(UPPER(TRIM(CLEAN(SUBSTITUTE(R14&""," "," "))))<>"",UPPER(TRIM(CLEAN(SUBSTITUTE(R14&""," "," "))))<>"IN",UPPER(TRIM(CLEAN(SUBSTITUTE(R14&""," "," "))))<>"OUT"),"CHECK: determination must be IN, OUT or blank",IF(AND(S14&""<>"",NOT(ISNUMBER(S14))),"CHECK: displaced rate must be a percentage",IF(AND(UPPER(TRIM(CLEAN(SUBSTITUTE(R14&""," "," "))))="",NOT(ISNUMBER(S14))),"CHECK: enter IN, OUT or a displaced rate",IF(SUMPRODUCT(--(Calc!$AL$5:$AL$254<>""))=0,"WAIT: Items not loaded yet",IF(COUNTIF(Calc!$AL$5:$AL$254,V14)=0,"CHECK: no Items row for this item and import country","OK")))))))) | AH14: =IF(UPPER(TRIM(CLEAN(SUBSTITUTE(Y14&""," "," "))))="","",COUNTIFS(Calc!$O$5:$O$254,UPPER(TRIM(CLEAN(SUBSTITUTE(Y14&""," "," ")))),Calc!$L$5:$L$254,"Y")) | AI14: =IF(AND(UPPER(TRIM(CLEAN(SUBSTITUTE(Y14&""," "," "))))="",UPPER(TRIM(CLEAN(SUBSTITUTE(Z14&""," "," "))))="",UPPER(TRIM(CLEAN(SUBSTITUTE(AA14&""," "," "))))="",UPPER(TRIM(CLEAN(SUBSTITUTE(AB14&""," "," "))))="",UPPER(TRIM(CLEAN(SUBSTITUTE(AE14&""," "," "))))="",AC14&""="",AD14&""="",AF14&""=""),"",IF(UPPER(TRIM(CLEAN(SUBSTITUTE(Y14&""," "," "))))="","CHECK: line ID missing",IF(NOT(ISNUMBER(AC14)),"CHECK: rate missing",IF(OR(AC14<0,AC14>10),"CHECK: rate must be 0% to 1000%",IF(SUMPRODUCT(--(UPPER(TRIM(CLEAN(SUBSTITUTE(rate_ID&""," "," "))))=UPPER(TRIM(CLEAN(SUBSTITUTE(Y14&""," "," "))))))>1,"CHECK: line ID listed twice",IF(AND(UPPER(TRIM(CLEAN(SUBSTITUTE(Z14&""," "," "))))<>"",SUMPRODUCT(--(UPPER(TRIM(CLEAN(SUBSTITUTE(scope_Group&""," "," "))))=UPPER(TRIM(CLEAN(SUBSTITUTE(Z14&""," "," "))))))=0),"CHECK: rate group not on the scope list",IF(AND(UPPER(TRIM(CLEAN(SUBSTITUTE(AA14&""," "," "))))<>"",SUMPRODUCT(--(UPPER(TRIM(CLEAN(SUBSTITUTE(scope_COO&""," "," "))))=UPPER(TRIM(CLEAN(SUBSTITUTE(AA14&""," "," "))))))=0),"CHECK: origin not on the origin list",IF(AND(UPPER(TRIM(CLEAN(SUBSTITUTE(AB14&""," "," "))))<>"",UPPER(TRIM(CLEAN(SUBSTITUTE(AB14&""," "," "))))<>"Y",UPPER(TRIM(CLEAN(SUBSTITUTE(AB14&""," "," "))))<>"N"),"CHECK: USMCA must be Y, N or blank",IF(AND(UPPER(TRIM(CLEAN(SUBSTITUTE(AE14&""," "," "))))<>"",UPPER(TRIM(CLEAN(SUBSTITUTE(AE14&""," "," "))))<>"FULL",UPPER(TRIM(CLEAN(SUBSTITUTE(AE14&""," "," "))))<>"PART"),"CHECK: duty base must be FULL, PART or blank",IF(OR(AND(AD14&""<>"",NOT(ISNUMBER(AD14))),AND(AF14&""<>"",NOT(ISNUMBER(AF14)))),"CHECK: earlier or displaced rate must be a percentage",IF(AC14>1,"NOTE: rate above 100%: check it was entered as a percentage","OK")))))))))))
